Workbook

Sheet GRADING
F1: FINAL EXAM
B5: question | C5: weight | D5: grade
B6: 1 | C6: 0.02 | D6: ='section 1 ( 1 to 9)'!R2 -> 10 | E6: 1.- Extract the project name. Make sure there are no spaces or extra codes. | H6: section 1 | K6: section weight
B7: 2 | C7: 0.02 | D7: ='section 1 ( 1 to 9)'!R3 -> 10 | E7: 2,. Extract the mail. No spaces or extra codes. Lowercase | K7: =SUM(C6:C15) -> 0.25
B8: 3 | C8: 0.02 | D8: ='section 1 ( 1 to 9)'!R4 -> 10 | E8: 3. change the format of the end date
B9: 4 | C9: 0.02 | D9: ='section 1 ( 1 to 9)'!R5 -> 10 | E9: 4.- calculate de total duration
B10: 5 | C10: 0.02 | D10: ='section 1 ( 1 to 9)'!R6 -> 10 | E10: 5.- calculate the duration in working days and consider the holidays given
B11: 6 | C11: 0.02 | D11: ='section 1 ( 1 to 9)'!R33 -> 10 | E11: 6.- Complete the table. Sum of number of Modules
B12: 7 | C12: 0.02 | D12: ='section 1 ( 1 to 9)'!R45 -> 10 | E12: 7.- Introduce 2 drop-down lists (data validation lists) to choose:Category (only Mobile and Web) Status (only Active and Completed)
B13: 8 | C13: 0.04 | D13: ='section 1 ( 1 to 9)'!R48 -> 10 | E13: 8.- highlight in the table above the whole row and column with a different color
B14: 9 | C14: 0.04 | D14: ='section 1 ( 1 to 9)'!R52 -> 10 | E14: 9.- Find the Category with the highest revenues in 2023 (start date) (with formulation, don't use tables).
B15: 9b | C15: 0.03 | D15: ='section 1 ( 1 to 9)'!R54 -> 10 | E15: 9b.- Using LET, return the Category with the highest AVERAGE Revenue among 2023 projects.
B16: 10 | C16: 0.1 | D16: ='sect 2 quesion 10'!Q1 -> 10 | E16: 10.- POWER QUERY: connect Tables 1-7 into a single Data Model table with 23 fields | H16: section 2 | K16: =SUM(C16:C21) -> 0.6
B17: 11 | C17: 0.1 | D17: ='section 2_ quesitons 11 to 15'!P13 -> 10 | E17: 11.- Time Series Analysis with Linear Trend Projection (3-period forecast)
B18: 12 | C18: 0.1 | D18: ='section 2_ quesitons 11 to 15'!P56 -> 10 | E18: 12.- POWER PIVOT: Column Chart of TotalAmount by Category with 3 slicers (CustomerCountry, ShippingCarrier, PaymentMethod)
B19: 13 | C19: 0.1 | D19: ='section 2_ quesitons 11 to 15'!P103 -> 10 | E19: 13.- Geographic Map + 2 shared slicers (Category, PaymentMethod) connected to Q14 too
B20: 14 | C20: 0.1 | D20: ='section 2_ quesitons 11 to 15'!P145 -> 10 | E20: 14.- Bubble Chart driven by the SAME slicers as Q13 (Category, PaymentMethod) - both visuals filter together
B21: 15 | C21: 0.1 | D21: ='section 2_ quesitons 11 to 15'!O195 -> 10 | E21: 15.- Combination Chart with Primary and Secondary Axes
B22: 16 | C22: 0.03 | D22: ='section 3 SQL 16 A 20'!Q6 -> 10 | E22: 16.- count the number of genres in table 2 | H22: section 3 | K22: =SUM(C22:C26) -> 0.15
B23: 17 | C23: 0.03 | D23: ='section 3 SQL 16 A 20'!Q22 -> 10 | E23: 17.- Inner join table 1 and 2 , and give the ID, Status, Sales and Genre given the condition that the sales where bigger than 520000. Name Table 1 as p1 and Table 2 as p2
B24: 18 | C24: 0.03 | D24: ='section 3 SQL 16 A 20'!Q37 -> 10 | E24: 18.- inner join now the previous with table 3 ( name it p3). Display a table with project name, status sales genre and country where the sales are bigger than 520000 and the country is UK
B25: 19 | C25: 0.03 | D25: ='section 3 SQL 16 A 20'!Q52 -> 10 | E25: 19.- SQL: INNER JOIN p1+p2+p3, return Project/Status/Sales/Genre/Country WHERE Sales>600K AND Status='Active'
B26: 20 | C26: 0.03 | D26: ='section 3 SQL 16 A 20'!Q67 -> 10 | E26: 20.- SQL: Compare LEFT vs RIGHT vs FULL JOIN on p1/p2 + short explanation of why row counts differ
B27: TOTAL | C27: =SUM(C6:C26) -> 1 | D27: =SUMPRODUCT(C6:C26,D6:D26) -> 10

Sheet section 1 ( 1 to 9)
A1: ID | B1: Project Name | C1: Email | D1: Start Date | E1: End Date | F1: Duration | G1: Working days | H1: Status | I1: Category | J1: Modules Count | K1: Revenue (USD) | R1: GRADE | S1: weight
A2: SW_0001@ AppBuilder | B2: AppBuilder | C2: sw_0001@ appbuilder.com | D2: 44941 | E2: 45641 | F2: 700 | G2: 498 | H2: Completed | I2: Mobile | J2: 1 | K2: 350000 | L2: 1.- Extract the Project Name from column A. Remove any spaces, hidden characters or extra codes. Place the result in column B (already started in B2). | R2: 10 | S2: =GRADING!C6 -> 0.02
A3: SW_0002﻿@WebFramework | D3: 44958 | E3: 45382 | F3: 425 | H3: Active | I3: Web | J3: 2 | K3: 420000 | L3: 2.- Extract the Email from column A. No spaces or extra codes. Output must be lowercase. Place result in column C (already started in C2). | R3: 10 | S3: =GRADING!C7 -> 0.02
A4: SW_0003@GameEngine‌ | D4: 44972 | E4: 45397 | F4: 426 | H4: On Hold | I4: Game | J4: 3 | K4: 530000 | L4: 3.- Change the format of the End Date column (column E) to a clean date format (m/d/yyyy). | R4: 10 | S4: =GRADING!C8 -> 0.02
A5: SW_0004 @Data​Analyzer | D5: 44986 | E5: 45413 | F5: 427 | H5: Completed | I5: Data | J5: 4 | K5: 480000 | L5: 4.- Calculate the total Duration (in days) between Start Date and End Date. Place result in column F (already started in F2). | R5: 10 | S5: =GRADING!C9 -> 0.02
A6: SW_0005@ CloudService‍ | D6: 45000 | E6: 45427 | F6: 427 | H6: Active | I6: Cloud | J6: 5 | K6: 620000 | L6: 5.- Calculate the Duration in WORKING DAYS between Start Date and End Date, excluding the holidays in M10:M29. Place result in column G (already started in G2). | R6: 10 | S6: =GRADING!C10 -> 0.02
A7: SW_0006@​SecuritySuite | D7: 45017 | E7: 45444 | F7: 427 | H7: On Hold | I7: Security | J7: 6 | K7: 590000
A8: SW_0007@MobileApp​ | D8: 45031 | E8: 45458 | F8: 427 | H8: Completed | I8: Mobile | J8: 7 | K8: 410000 | M8: Holidays List:
A9: SW_0008@E-commerce‌ | D9: 45047 | E9: 45474 | F9: 427 | H9: Active | I9: Web | J9: 8 | K9: 550000 | M9: Date | N9: Day of Week
A10: SW_0009@ VR​Framework | D10: 45061 | E10: 45488 | F10: 427 | H10: On Hold | I10: Game | J10: 9 | K10: 670000 | M10: 44927 | N10: Sunday
A11: SW_00​10@AnalyticsPlatform | D11: 45078 | E11: 45505 | F11: 427 | H11: Completed | I11: Data | J11: 10 | K11: 720000 | M11: 45075 | N11: Monday
A12: SW_00‍11@ServerlessAPI | D12: 45092 | E12: 45519 | F12: 427 | H12: Active | I12: Cloud | J12: 11 | K12: 680000 | M12: 45111 | N12: Tuesday
A13: SW_0012@Identity‍Management | D13: 45108 | E13: 45536 | F13: 428 | H13: On Hold | I13: Security | J13: 12 | K13: 590000 | M13: 45173 | N13: Monday
A14: SW_0013@MobileSDK﻿ | D14: 45122 | E14: 45550 | F14: 428 | H14: Completed | I14: Mobile | J14: 13 | K14: 430000 | M14: 45253 | N14: Thursday
A15: SW_001‌4@ContentManagement | D15: 45139 | E15: 45566 | F15: 427 | H15: Active | I15: Web | J15: 14 | K15: 510000 | M15: 45285 | N15: Monday
A16: ​SW_0015@ARExperience | D16: 45153 | E16: 45580 | F16: 427 | H16: On Hold | I16: Game | J16: 15 | K16: 620000 | M16: 45292 | N16: Monday
A17: SW_0016@B﻿igDataPipeline | D17: 45170 | E17: 45597 | F17: 427 | H17: Completed | I17: Data | J17: 16 | K17: 690000 | M17: 45306 | N17: Monday
A18: ﻿SW_0017@MicroservicesArch | D18: 45184 | E18: 45611 | F18: 427 | H18: Active | I18: Cloud | J18: 17 | K18: 730000 | M18: 45341 | N18: Monday
A19: SW_0018‌@CyberSecurity | D19: 45200 | E19: 45627 | F19: 427 | H19: On Hold | I19: Security | J19: 18 | K19: 640000 | M19: 45439 | N19: Monday
A20: SW_0019@MobileWallet‌ | D20: 45214 | E20: 45641 | F20: 427 | H20: Completed | I20: Mobile | J20: 19 | K20: 470000 | M20: 45477 | N20: Thursday
A21: SW‌_0020@SearchEngine | D21: 45231 | E21: 45658 | F21: 427 | H21: Active | I21: Web | J21: 20 | K21: 580000 | M21: 45537 | N21: Monday
... A29: SW_0028@DataWarehouse​ | D29: 45352 | E29: 45778 | F29: 427 | H29: Completed | I29: Data | J29: 8 | K29: 710000 | M29: 45842 | N29: Friday
A30: SW_0029@‌CloudStorage | D30: 45366 | E30: 45792 | F30: 427 | H30: Active | I30: Cloud | J30: 9 | K30: 640000
A31: SW_0030@Aut‌hentication | D31: 45383 | E31: 45809 | F31: 427 | H31: On Hold | I31: Security | J31: 10 | K31: 600000
A32: SW_0031@AppOpt‍imizer | D32: 45397 | E32: 45823 | F32: 427 | H32: Completed | I32: Mobile | J32: 11 | K32: 420000
A33: SW_‌0032@WebAPI | D33: 45413 | E33: 45839 | F33: 427 | H33: Active | I33: Web | J33: 12 | K33: 490000 | L33: 6.- Complete the small summary table below: total number of Modules per Category. Use a formula (SUMIF / SUMIFS), not manual values. | R33: 10 | S33: =GRADING!C11 -> 0.02
A34: SW_​0033@GameAssets | D34: 45427 | E34: 45853 | F34: 427 | H34: On Hold | I34: Game | J34: 13 | K34: 650000 | M34: Active | N34: Completed
A35: SW_0034﻿@DataMining | D35: 45444 | E35: 45870 | F35: 427 | H35: Completed | I35: Data | J35: 14 | K35: 680000 | L35: =I2 -> Mobile
A36: SW_0035@Cl﻿oudDeployment | D36: 45458 | E36: 45884 | F36: 427 | H36: Active | I36: Cloud | J36: 15 | K36: 710000 | L36: =I33 -> Web
A37: ‍SW_0036@ThreatDetection | D37: 45474 | E37: 45901 | F37: 428 | H37: On Hold | I37: Security | J37: 16 | K37: 620000 | L37: =I34 -> Game
A38: SW_0037@﻿MobilePayment | D38: 45488 | E38: 45915 | F38: 428 | H38: Completed | I38: Mobile | J38: 17 | K38: 440000 | L38: =I35 -> Data
A39: SW_0038@WebHosting‍ | D39: 45505 | E39: 45931 | F39: 427 | H39: Active | I39: Web | J39: 18 | K39: 520000 | L39: Cloud
A40: SW_‍0039@GamePhysics | D40: 45519 | E40: 45945 | F40: 427 | H40: On Hold | I40: Game | J40: 19 | K40: 640000 | L40: Security
A41: SW_0040@Da​taClassification | D41: 45536 | E41: 45962 | F41: 427 | H41: Completed | I41: Data | J41: 20 | K41: 700000
A42: SW_0041@CloudIn‌frastructure | D42: 45550 | E42: 45976 | F42: 427 | H42: Active | I42: Cloud | J42: 1 | K42: 750000
A43: SW_0042@DDoSProt﻿ection | D43: 45566 | E43: 45992 | F43: 427 | H43: On Hold | I43: Security | J43: 2 | K43: 630000
A44: SW_0043@PushNot﻿ifications | D44: 45580 | E44: 46006 | F44: 427 | H44: Completed | I44: Mobile | J44: 3 | K44: 410000 | L44: 7.- Add 2 drop-down lists (Data Validation > List): one for Category restricted to {Mobile, Web}, and one for Status restricted to {Active, Completed}.
A45: SW_0044@WebPerfo‍rmance | D45: 45597 | E45: 46023 | F45: 427 | H45: Active | I45: Web | J45: 4 | K45: 540000 | L45: Genre | R45: 10 | S45: =GRADING!C12 -> 0.02
A46: SW_0045@GameSound | D46: 45611 | E46: 46037 | F46: 427 | H46: On Hold | I46: Game | J46: 5 | K46: 680000 | L46: Status
A47: SW_0046@DataPred﻿iction | D47: 45627 | E47: 46054 | F47: 428 | H47: Completed | I47: Data | J47: 6 | K47: 730000
...

Sheet section 2_DATA
A1: Table 1 | I1: Table 2 | J1: ( CREATE THE DELIVERY YEAR BASED ON THIS TABLE) | P1: Table 4
A2: ProductID | B2: ProductName | C2: Category | D2: UnitPrice | E2: Stock | F2: Status | I2: OrderID | J2: ProductID | K2: Quantity | L2: OrderDate | M2: ShipmentDate | N2: SalePrice | P2: CustomerID | Q2: FullName | R2: Email | S2: Country | T2: Region | U2: CustomerType | X2: Table 6
A3: P001 | B3: Laptop Pro | C3: Electronics | D3: 1299.99 | E3: 45 | F3: Active | I3: ORD001 | J3: P001 | K3: 2 | L3: 1/15/2024 | M3: 1/18/2024 | N3: 2599.98 | P3: C001 | Q3: John Smith | R3: john.smith@email.com | S3: United States | T3: North | U3: Regular | X3: ShipmentID | Y3: OrderID | Z3: DispatchDate | AA3: EstimatedDelivery | AB3: ActualDelivery | AC3: ShippingCarrier
A4: P002 | B4: Office Chair | C4: Furniture | D4: 249.99 | E4: 120 | F4: Active | I4: ORD002 | J4: P003 | K4: 5 | L4: 1/16/2024 | M4: 1/19/2024 | N4: 899.95 | P4: C002 | Q4: Emma Johnson | R4: emma.j@email.com | S4: Canada | T4: East | U4: Premium | X4: SHP001 | Y4: ORD001 | Z4: 1/18/2024 | AA4: 1/25/2024 | AB4: 1/24/2024 | AC4: FedEx
A5: P003 | B5: Wireless Headphones | C5: Electronics | D5: 179.99 | E5: 78 | F5: Active | I5: ORD003 | J5: P005 | K5: 3 | L5: 1/17/2024 | M5: 1/20/2024 | N5: 269.97 | P5: C003 | Q5: Michael Brown | R5: mbrown@email.com | S5: United Kingdom | T5: Central | U5: Premium | X5: SHP002 | Y5: ORD002 | Z5: 1/19/2024 | AA5: 1/26/2024 | AB5: 1/26/2024 | AC5: UPS
A6: P004 | B6: Desk Lamp | C6: Home Goods | D6: 39.99 | E6: 210 | F6: Active | I6: ORD004 | J6: P012 | K6: 4 | L6: 1/18/2024 | M6: 1/21/2024 | N6: 999.96 | P6: C004 | Q6: Sophia Garcia | R6: sgarcia@email.com | S6: Mexico | T6: South | U6: Regular | X6: SHP003 | Y6: ORD003 | Z6: 1/20/2024 | AA6: 1/27/2024 | AB6: 1/28/2024 | AC6: DHL
A7: P005 | B7: Coffee Maker | C7: Kitchen | D7: 89.99 | E7: 65 | F7: Active | I7: ORD005 | J7: P008 | K7: 1 | L7: 1/19/2024 | M7: 1/22/2024 | N7: 149.99 | P7: C005 | Q7: Daniel Wilson | R7: danielw@email.com | S7: Australia | T7: West | U7: Regular | X7: SHP004 | Y7: ORD004 | Z7: 1/21/2024 | AA7: 1/28/2024 | AB7: 1/27/2024 | AC7: FedEx
A8: P006 | B8: Bluetooth Speaker | C8: Electronics | D8: 129.99 | E8: 92 | F8: Active | I8: ORD006 | J8: P006 | K8: 3 | L8: 1/20/2024 | M8: 1/23/2024 | N8: 389.97 | P8: C006 | Q8: Olivia Martinez | R8: oliviam@email.com | S8: United States | T8: East | U8: Premium | X8: SHP005 | Y8: ORD005 | Z8: 1/22/2024 | AA8: 1/29/2024 | AB8: 1/30/2024 | AC8: UPS
A9: P007 | B9: Ergonomic Desk | C9: Furniture | D9: 399.99 | E9: 34 | F9: Active | I9: ORD007 | J9: P004 | K9: 7 | L9: 1/21/2024 | M9: 1/24/2024 | N9: 279.93 | P9: C007 | Q9: James Anderson | R9: janderson@email.com | S9: Canada | T9: North | U9: Regular | X9: SHP006 | Y9: ORD006 | Z9: 1/23/2024 | AA9: 1/30/2024 | AB9: 1/29/2024 | AC9: DHL
A10: P008 | B10: External Hard Drive | C10: Electronics | D10: 149.99 | E10: 56 | F10: Active | I10: ORD008 | J10: P009 | K10: 2 | L10: 1/22/2024 | M10: 1/25/2024 | N10: 119.98 | P10: C008 | Q10: Isabella Thomas | R10: isabellatom@email.com | S10: United Kingdom | T10: West | U10: Premium | X10: SHP007 | Y10: ORD007 | Z10: 1/24/2024 | AA10: 1/31/2024 | AB10: 2/1/2024 | AC10: FedEx
A11: P009 | B11: Cutlery Set | C11: Kitchen | D11: 59.99 | E11: 87 | F11: Active | I11: ORD009 | J11: P013 | K11: 3 | L11: 1/23/2024 | M11: 1/26/2024 | N11: 1049.97 | P11: C009 | Q11: William Taylor | R11: wtaylor@email.com | S11: Mexico | T11: Central | U11: Regular | X11: SHP008 | Y11: ORD008 | Z11: 1/25/2024 | AA11: 2/1/2024 | AB11: 2/1/2024 | AC11: UPS
A12: P010 | B12: Smart Watch | C12: Electronics | D12: 299.99 | E12: 41 | F12: On Hold | I12: ORD010 | J12: P007 | K12: 1 | L12: 1/24/2024 | M12: 1/27/2024 | N12: 399.99 | P12: C010 | Q12: Charlotte Lee | R12: charlee@email.com | S12: Australia | T12: South | U12: Premium | X12: SHP009 | Y12: ORD009 | Z12: 1/26/2024 | AA12: 2/2/2024 | AB12: 2/3/2024 | AC12: DHL
A13: P011 | B13: Dining Table | C13: Furniture | D13: 599.99 | E13: 23 | F13: Active | I13: ORD011 | J13: P014 | K13: 3 | L13: 2/1/2024 | M13: 2/4/2024 | N13: 3899.97 | X13: SHP010 | Y13: ORD010 | Z13: 1/27/2024 | AA13: 2/3/2024 | AB13: 2/2/2024 | AC13: FedEx
A14: P012 | B14: Blender | C14: Kitchen | D14: 79.99 | E14: 59 | F14: Discontinued | I14: ORD012 | J14: P010 | K14: 2 | L14: 2/2/2024 | M14: 2/5/2024 | N14: 599.98
A15: P013 | B15: Monitor | C15: Electronics | D15: 349.99 | E15: 38 | F15: Active | I15: ORD013 | J15: P011 | K15: 1 | L15: 2/3/2024 | M15: 2/6/2024 | N15: 599.99 | P15: Table 5 | X15: Table 7
A16: P014 | B16: Standing Desk | C16: Furniture | D16: 499.99 | E16: 19 | F16: On Hold | I16: ORD014 | J16: P015 | K16: 4 | L16: 2/4/2024 | M16: 2/7/2024 | N16: 519.96 | P16: SupplierID | Q16: SupplierName | R16: ProductID | S16: City | T16: Country | U16: Continent | V16: LeadTime | X16: ShipmentID | Y16: OrderID | Z16: DispatchDate | AA16: EstimatedDelivery | AB16: ActualDelivery | AC16: ShippingCarrier
A17: P015 | B17: Smart Thermostat | C17: Home Goods | D17: 129.99 | E17: 62 | F17: Active | I17: ORD015 | J17: P003 | K17: 6 | L17: 2/5/2024 | M17: 2/8/2024 | N17: 1079.94 | P17: SUP001 | Q17: TechGlobal | R17: P001 | S17: Tokyo | T17: Japan | U17: Asia | V17: 14 | X17: SHP011 | Y17: ORD011 | Z17: 2/4/2024 | AA17: 2/11/2024 | AB17: 2/10/2024 | AC17: UPS
I18: ORD016 | J18: P002 | K18: 2 | L18: 3/1/2024 | M18: 3/4/2024 | N18: 499.98 | P18: SUP002 | Q18: FurniturePlus | R18: P002 | S18: Milan | T18: Italy | U18: Europe | V18: 21 | X18: SHP012 | Y18: ORD012 | Z18: 2/5/2024 | AA18: 2/12/2024 | AB18: 2/13/2024 | AC18: DHL
I19: ORD017 | J19: P006 | K19: 4 | L19: 3/2/2024 | M19: 3/5/2024 | N19: 519.96 | P19: SUP003 | Q19: SoundMasters | R19: P003 | S19: Seoul | T19: South Korea | U19: Asia | V19: 10 | X19: SHP013 | Y19: ORD013 | Z19: 2/6/2024 | AA19: 2/13/2024 | AB19: 2/12/2024 | AC19: FedEx
I20: ORD018 | J20: P013 | K20: 2 | L20: 3/3/2024 | M20: 3/6/2024 | N20: 699.98 | P20: SUP004 | Q20: HomeEssentials | R20: P004 | S20: Barcelona | T20: Spain | U20: Europe | V20: 15 | X20: SHP014 | Y20: ORD014 | Z20: 2/7/2024 | AA20: 2/14/2024 | AB20: 2/15/2024 | AC20: UPS
I21: ORD019 | J21: P004 | K21: 10 | L21: 3/4/2024 | M21: 3/7/2024 | N21: 399.9 | P21: SUP005 | Q21: KitchenPro | R21: P005 | S21: Chicago | T21: United States | U21: North America | V21: 7 | X21: SHP015 | Y21: ORD015 | Z21: 2/8/2024 | AA21: 2/15/2024 | AB21: 2/14/2024 | AC21: DHL
A22: FOLLOW NEXT PAGE INSTRUCTIONS | I22: ORD020 | J22: P008 | K22: 3 | L22: 3/5/2024 | M22: 3/8/2024 | N22: 449.97 | P22: SUP006 | Q22: AudioTech | R22: P006 | S22: Berlin | T22: Germany | U22: Europe | V22: 12 | X22: SHP016 | Y22: ORD016 | Z22: 3/4/2024 | AA22: 3/11/2024 | AB22: 3/12/2024 | AC22: FedEx
P23: SUP007 | Q23: ErgonomicsInc | R23: P007 | S23: Stockholm | T23: Sweden | U23: Europe | V23: 18 | X23: SHP017 | Y23: ORD017 | Z23: 3/5/2024 | AA23: 3/12/2024 | AB23: 3/11/2024 | AC23: UPS
P24: SUP008 | Q24: DataStorage | R24: P008 | S24: Taipei | T24: Taiwan | U24: Asia | V24: 14 | X24: SHP018 | Y24: ORD018 | Z24: 3/6/2024 | AA24: 3/13/2024 | AB24: 3/14/2024 | AC24: DHL
I25: Table 3 | P25: SUP009 | Q25: CulinaryWorks | R25: P009 | S25: Paris | T25: France | U25: Europe | V25: 16 | X25: SHP019 | Y25: ORD019 | Z25: 3/7/2024 | AA25: 3/14/2024 | AB25: 3/13/2024 | AC25: FedEx
I26: OrderID | J26: CustomerID | K26: PaymentMethod | L26: TotalAmount | M26: Discount | N26: FinalAmount | P26: SUP010 | Q26: SmartWear | R26: P010 | S26: San Francisco | T26: United States | U26: North America | V26: 9 | X26: SHP020 | Y26: ORD020 | Z26: 3/8/2024 | AA26: 3/15/2024 | AB26: 3/16/2024 | AC26: UPS
I27: ORD001 | J27: C003 | K27: Credit Card | L27: 2599.98 | M27: 0 | N27: 2599.98 | P27: SUP011 | Q27: DiningDecor | R27: P011 | S27: Toronto | T27: Canada | U27: North America | V27: 20
I28: ORD002 | J28: C007 | K28: PayPal | L28: 899.95 | M28: 0 | N28: 899.95 | P28: SUP012 | Q28: KitchenAppliances | R28: P012 | S28: Melbourne | T28: Australia | U28: Oceania | V28: 25
I29: ORD003 | J29: C001 | K29: Credit Card | L29: 269.97 | M29: 0 | N29: 269.97 | P29: SUP013 | Q29: DisplayTech | R29: P013 | S29: Shenzhen | T29: China | U29: Asia | V29: 15
I30: ORD004 | J30: C006 | K30: Debit Card | L30: 999.96 | M30: 100 | N30: 899.96 | P30: SUP014 | Q30: OfficeSuppliers | R30: P014 | S30: London | T30: United Kingdom | U30: Europe | V30: 17
I31: ORD005 | J31: C008 | K31: PayPal | L31: 149.99 | M31: 0 | N31: 149.99 | P31: SUP015 | Q31: SmartHome | R31: P015 | S31: Helsinki | T31: Finland | U31: Europe | V31: 13
I32: ORD006 | J32: C002 | K32: Credit Card | L32: 389.97 | M32: 0 | N32: 389.97
I33: ORD007 | J33: C004 | K33: Bank Transfer | L33: 279.93 | M33: 0 | N33: 279.93
I34: ORD008 | J34: C010 | K34: Credit Card | L34: 119.98 | M34: 0 | N34: 119.98
I35: ORD009 | J35: C005 | K35: PayPal | L35: 1049.97 | M35: 105 | N35: 944.97
I36: ORD010 | J36: C009 | K36: Debit Card | L36: 399.99 | M36: 0 | N36: 399.99
I37: ORD011 | J37: C002 | K37: Credit Card | L37: 3899.97 | M37: 390 | N37: 3509.97
I38: ORD012 | J38: C001 | K38: PayPal | L38: 599.98 | M38: 0 | N38: 599.98
I39: ORD013 | J39: C006 | K39: Credit Card | L39: 599.99 | M39: 0 | N39: 599.99
I40: ORD014 | J40: C003 | K40: Bank Transfer | L40: 519.96 | M40: 52 | N40: 467.96
...

Sheet sect 2 quesion 10
A1: 10.- Using POWER QUERY ONLY, connect Tables 1 to 7 from sheet 'section 2_DATA' into a single consolidated table. Add this final table to the Data Model. Print the FINAL result in a NEW SHEET (you will use it for Section 2 questions 11-15). Make sure the field names match the headers listed below exactly. | Q1: 10 | R1: =GRADING!C15 -> 0.03
B2: Append the two split shipping tables (Table 6 + Table 7) using Power Query
B3: Create a 'DeliveryYear' calculated column (extract YEAR from ActualDelivery)
B4: Merge all tables using consistent key columns (ProductID, OrderID, CustomerID, ShipmentID, SupplierID via ProductID)
B5: The final result must contain EXACTLY the 23 fields listed in row 18 below
B6: PRINT the final result in a NEW SHEET (this is the source for questions 11-15)
B8: RECOMMENDATIONS | J8: STEPS
B9: THERE ARE 7 TABLES¡¡¡¡¡ | J9: merge table 1 and 2 = merge 1
B10: _FOLLOW THE STEPS GIVEN TO GET THE RESULT | J10: merge merge1 with table 3= merge 2
B11: _MAINTAIN COHERENT COLUMN NAMES | J11: merge merge 2 with table 4= merge 3
B12: _MATCH THE CORRECT COLUMNS PLEASE | J12: merge merge 3 with table 5= merge 4
B13: _ DO EVERYTHING WITH POWER QUERY | J13: append table6 and 7= Append 1
B14: if you have any problem with the date format, selct the column right-click/change type/ use locale/Date and usa | J14: merge merge4 and appen1=merge5( solution)
A17: I HIGHLY RECOMMEND TO NAME THE TABLES AND FOLLOW THE ORDER GIVEN
A18: OrderID | B18: ProductID | C18: ProductName | D18: Category | E18: UnitPrice | F18: CustomerID | G18: CustomerName | H18: CustomerCountry | I18: OrderDate | J18: ShipmentID | K18: DispatchDate | L18: EstimatedDelivery | M18: ActualDelivery | N18: ShippingCarrier | O18: SupplierID | P18: SupplierName | Q18: SupplierCountry | R18: Quantity | S18: SalePrice | T18: TotalAmount | U18: Discount | V18: FinalAmount
A54: ( DO NOT DO IT MANUALLY, NO GRADE FOR IT).

Sheet section 2_ quesitons 11 to 15
R1: SCROLL UNITL THE END
A2: Requirements for All Visualizations
A3: Use consistent formatting and color schemes across all charts
A4: Add appropriate titles and axis labels to all charts
A5: Include data labels where they add value without cluttering
A6: Ensure all charts are connected to the Data Model, not to direct cell ranges
A7: Include a text box with key insights from each visualization ( a few words with the moan idea)
A8: scroll down until question 15
A13: 11.- Time Series Analysis with Linear Trend Projection | P13: =(P17+P24)/2 -> 10 | Q13: =GRADING!C17 -> 0.1
A15: Build a time-based PivotTable + line chart from the DATA MODEL showing monthly Quantity sold, with a LINEAR trendline.
A17: 1. Create a PivotTable from your Data Model | P17: 10 | Q17: 0.05
B18: 1.1. Add fields:
B19: ROWS: OrderDate (grouped by MONTH)
B21: VALUES: Quantity (Sum)
A23: 2. Create a line chart from this PivotTable
B24: 2.1. Add a LINEAR trendline: | P24: 10 | Q24: 0.05
B25: 2.2.- Display the R-squared value on the chart. Set 'Forecast forward' = 3 periods. Report the value of the trendline at the 3rd forecast period.
A26: do it here please | N26: Include a text box with key insights
A56: =GRADING!E18 -> 12.- POWER PIVOT: Column Chart of TotalAmount by Category with 3 slicers (CustomerCountry, ShippingCarrier, PaymentMethod) | P56: =(P62+P68)/2 -> 10 | Q56: =GRADING!C18 -> 0.1
B57: Build a column chart of TotalAmount by ProductCategory from the DATA MODEL, with 3 connected slicers.
B59: 1. Create a PivotTable with:
B60: ROWS: Category (from Table 1, via the merged table)
B61: VALUES: TotalAmount (Sum)
B62: 2. Create a bar chart from this PivotTable | P62: 10 | Q62: 0.05
B63: 3. Add slicers for:
B64: CustomerCountry
B65: ShippingCarrier
B66: PaymentMethod
B67: (hint: you can add these fields to the pivot but dont display them)
B68: 4. Format slicers vertically and CONNECT all three slicers to the PivotTable. | P68: 10 | Q68: 0.05
B70: do it here please | O70: Include a text box with key insights
A103: 13.- Geographic Map Visualization (with shared slicers) | P103: 10 | Q103: =GRADING!C19 -> 0.1
B104: Create a Map chart showing sales by country using the Data Model. The slicers below will also drive Q14 (bubble chart) - both visuals must update simultaneously.
B106: 1. Insert a Map chart sourced from a PivotTable on the Data Model
B107: 2. Set up the data:
C108: Locations: CustomerCountry (or SupplierCountry)
C109: Values: Sum of FinalAmount
B110: 3. Format the map: appropriate color scale, data labels (country + value), legend visible
B111: 4. Insert TWO slicers: Category and PaymentMethod
B112: 5. CONNECT both slicers to the Map PivotTable AND to the Bubble PivotTable in Q14 (Slicer > Report Connections > tick both pivots) so a single click filters BOTH visuals simultaneously
...

Sheet section 3 SQL  16 A 20
A1: upload table 1, 2 and 3 in https://sqliteonline.com/
A6: 16.- Count the number of DISTINCT genres in Table 2 (p2). Return a single number with column alias 'genre_count'. | Q6: 10 | R6: =GRADING!C22 -> 0.03
A7: answer here: copy paste the query ant the resulting table
A22: 17.- INNER JOIN Table 1 (alias p1) and Table 2 (alias p2). Return ID, Status, Sales, Genre WHERE Sales > 520000. | Q22: 10 | R22: =GRADING!C24 -> 0.03
A23: answer here: copy paste the query ant the resulting table
A37: 18.- INNER JOIN the previous result with Table 3 (alias p3). Return Project Name, Status, Sales, Genre, Country WHERE Sales > 520000 AND Country = 'UK'. | Q37: 10
A38: answer here: copy paste the query ant the resulting table
A52: 19.- INNER JOIN all THREE tables (p1, p2, p3 in a single query). Return Project Name, Status, Sales, Genre and Country WHERE Sales > 600000 AND Status = 'Active'. Order results by Sales DESC. | Q52: 10 | R52: =GRADING!C25 -> 0.03
A53: answer here: copy paste the query and the resulting table
A67: 20.- Compare LEFT JOIN vs RIGHT JOIN (vs FULL OUTER JOIN if your SQL engine supports it) between p1 and p2 on the ID column. Write THREE separate queries (one LEFT, one RIGHT, one FULL) returning ID, Project Name and Genre. Then in 1-2 sentences below the queries, explain WHY the row counts differ (which rows appear in one but not the other, and what NULLs mean in each result). | Q67: 10 | R67: =GRADING!C26 -> 0.03
A68: answer here: paste the 3 queries, the 3 resulting tables, and your short explanation

Sheet PRINT - All Questions
A1: FINAL EXAM - ALL QUESTIONS
A2: Print-friendly version. Source-of-truth answers go in the original sheets.
A4: SECTION 1 - Excel Basics & Formulas (Sheet: 'section 1 ( 1 to 9)') - Weight 25%
A6: Q1 (2%) | B6: Extract the Project Name from column A. Remove any spaces, hidden characters or extra codes. Place the result in column B (already started in B2).
A7: Q2 (2%) | B7: Extract the Email from column A. No spaces or extra codes. Output must be lowercase. Place result in column C (already started in C2).
A8: Q3 (2%) | B8: Change the format of the End Date column (column E) to a clean date format (m/d/yyyy).
A9: Q4 (2%) | B9: Calculate the total Duration (in days) between Start Date and End Date. Place result in column F (already started in F2).
A10: Q5 (2%) | B10: Calculate the Duration in WORKING DAYS between Start Date and End Date, excluding the holidays in M10:M29. Place result in column G (already started in G2).
A11: Q6 (2%) | B11: Complete the small summary table below: total number of Modules per Category. Use a formula (SUMIF / SUMIFS), not manual values.
A12: Q7 (2%) | B12: Add 2 drop-down lists (Data Validation > List): one for Category restricted to {Mobile, Web}, and one for Status restricted to {Active, Completed}.
A13: Q8 (4%) | B13: In the main table (A1:K56), apply Conditional Formatting that highlights the ENTIRE ROW and ENTIRE COLUMN of the active cell with a different color (cross-hair highlight).
A14: Q9 (4%) | B14: Find the Category with the HIGHEST total Revenue among projects whose Start Date is in 2023. Use formulas only (no PivotTable, no Excel Tables).
A15: Q9b (3%) | B15: Using the LET function, compute the AVERAGE Revenue per Category for projects whose Start Date is in 2023, and return the Category with the highest average. Your formula MUST use LET to name intermediate variables (e.g., years, categories, avgs) and a single final expression. No helper cells.
A17: SECTION 2 - Power Query, Power Pivot & Visualizations - Weight 60%
A18: Data source: sheet 'section 2_DATA' (Tables 1-7). Final consolidated table from Q10 is the input for Q11-15.
A20: Q10 (10%) - Sheet 'sect 2 quesion 10' | B20: Using POWER QUERY ONLY, connect Tables 1-7 from 'section 2_DATA' into a single consolidated table. Add the result to the Data Model and PRINT it in a NEW SHEET (used as input for Q11-15). Steps: - Append the two split shipping tables (Table 6 + Table 7) - Create a 'DeliveryYear' calculated column (YEAR of ActualDelivery) - Merge all tables using consistent keys (ProductID, OrderID, CustomerID, ShipmentID, SupplierID via ProductID) - Final result must contain EXACTLY 23 fields: ProductID, ProductName, Category, UnitPrice, CustomerID, CustomerName, CustomerCountry, OrderDate, ShipmentID, DispatchDate, EstimatedDelivery, ActualDelivery, ShippingCarrier, SupplierID, SupplierName, SupplierCountry, Quantity, SalePrice, TotalAmount, Discount, FinalAmount, DeliveryYear, PaymentMethod Merge order (suggested): merge1 = Table1 + Table2 merge2 = merge1 + Table3 merge3 = merge2 + Table4 merge4 = merge3 + Table5 append1 = Table6 + Table7 merge5 = merge4 + append1 <- final
A22: Q11 (10%) | B22: TIME SERIES with LINEAR TREND PROJECTION. Build a time-based PivotTable + line chart from the DATA MODEL showing monthly Quantity sold, with a LINEAR trendline. 1. Create a PivotTable from the Data Model 1.1 ROWS: OrderDate (grouped by MONTH) 1.2 VALUES: Quantity (Sum) 2. Create a line chart from this PivotTable 2.1 Add a LINEAR trendline 2.2 Display the R-squared value on the chart. Set 'Forecast forward' = 3 periods. Report the value of the trendline at the 3rd forecast period.
A23: Q12 (10%) | B23: POWER PIVOT - Column Chart with Multiple Slicers. Build a column chart of TotalAmount by Category from the DATA MODEL, with 3 connected slicers. 1. PivotTable: ROWS = Category, VALUES = TotalAmount (Sum) 2. Build a column/bar chart from this PivotTable 3. Add 3 slicers: CustomerCountry, ShippingCarrier, PaymentMethod (you can add these fields to the pivot but don't display them) 4. Format slicers vertically and CONNECT all 3 slicers to the PivotTable
A24: Q13 (10%) | B24: GEOGRAPHIC MAP VISUALIZATION (with shared slicers). The slicers below also drive Q14 - both visuals must update simultaneously. 1. Insert a Map chart sourced from a PivotTable on the Data Model 2. Data: - Locations: CustomerCountry (or SupplierCountry) - Values: Sum of FinalAmount 3. Format: appropriate color scale, data labels (country + value), legend visible 4. Insert TWO slicers: Category and PaymentMethod 5. CONNECT both slicers to the Map PivotTable AND to the Bubble PivotTable in Q14 (Slicer > Report Connections > tick BOTH pivots) so a single click filters both visuals 6. Add a text box with 1-2 key insights
A25: Q14 (10%) | B25: BUBBLE CHART for Multi-dimensional Analysis (with shared slicers). Driven by the SAME slicers as Q13 - filtering one slicer must update Q13 (Map) and Q14 (Bubble) at the same time. 1. PivotTable from the Data Model: ROWS: ProductName VALUES: Quantity (Sum) -> X-axis ; UnitPrice (Average) -> Y-axis ; TotalAmount (Sum) -> bubble size 2. Insert a Bubble chart from this PivotTable 3. Format: clear X/Y axis labels, data labels on key bubbles, descriptive title 4. CONNECT the SAME 2 slicers from Q13 (Category, PaymentMethod) to this PivotTable too 5. Verify: clicking a slicer value updates BOTH the Map (Q13) and the Bubble chart (Q14) simultaneously 6. Add a text box with 1-2 key insights
A26: Q15 (10%) | B26: COMBINATION CHART with Primary and Secondary Axes. Build a combo chart (columns + line on a secondary axis) from the Data Model showing VOLUME and VALUE per Category. 1. PivotTable: ROWS = Category, VALUES = Quantity (Sum) and FinalAmount (Sum) 2. Insert > Charts > Combo > 'Custom Combination' - Quantity series: Clustered Column (PRIMARY / left axis) - FinalAmount series: Line, TICK 'Secondary Axis' (right axis) 3. Formatting: - Chart title (e.g. 'Volume vs Value by Category') - PRIMARY axis title: 'Quantity (units)' ; SECONDARY axis title: 'Final Amount (USD)' - Different colors for the two series, legend at the bottom - Data labels on the LINE series only - Format the secondary axis as currency ($#,##0) 4. Add a text box with 1-2 key insights (which Category has highest volume vs highest value, and whether they match)
A28: SECTION 3 - SQL (Sheet: 'section 3 SQL 16 A 20') - Weight 15%
A29: Upload Tables 1, 2 and 3 to https://sqliteonline.com/. Alias: Table 1 = p1, Table 2 = p2, Table 3 = p3.
A31: Q16 (3%) | B31: Count the number of DISTINCT genres in Table 2 (p2). Return a single number with column alias 'genre_count'.
A32: Q17 (3%) | B32: INNER JOIN p1 and p2. Return ID, Status, Sales, Genre WHERE Sales > 520000.
A33: Q18 (3%) | B33: INNER JOIN the previous result with p3. Return Project Name, Status, Sales, Genre, Country WHERE Sales > 520000 AND Country = 'UK'.
A34: Q19 (3%) | B34: INNER JOIN all THREE tables (p1, p2, p3) in a single query. Return Project Name, Status, Sales, Genre and Country WHERE Sales > 600000 AND Status = 'Active'. Order results by Sales DESC.
A35: Q20 (3%) | B35: Compare LEFT JOIN vs RIGHT JOIN (vs FULL OUTER JOIN if your SQL engine supports it) between p1 and p2 on the ID column. Write THREE separate queries (one LEFT, one RIGHT, one FULL) returning ID, Project Name and Genre. Then in 1-2 sentences below the queries, explain WHY the row counts differ (which rows appear in one but not the other, and what NULLs mean in each result).
A37: END OF EXAM
